Workbook

Sheet Sheet0
A1: DC：林口DC
A2: 配別名稱：常溫
A3: 進貨指定日：2022-12-03
A4: 不可大車 | B4: 車次 | C4: ID | D4: 店名 | E4: 表定時間 | F4: 預定時間 | G4: 貨量 | H4: 裝載率
B5: 2M | D5: 林口ＤＣ | G5: 2.81 | H5: 0.39027778
A6: False | B6: 2M02 | C6: =_xlfn.XLOOKUP(D6,工作表1!C:C,工作表1!A:A) -> 1001018520 | D6: 高鐵二店 | E6: 2022-12-02 18:30:00 | F6: 2022-12-02 18:30:00 | G6: 1.31
A7: False | B7: 2M03 | C7: =_xlfn.XLOOKUP(D7,工作表1!C:C,工作表1!A:A) -> 1001018687 | D7: 台鐵一店 | E7: 2022-12-02 19:00:00 | F7: 2022-12-02 19:00:00 | G7: 0.95
A8: False | B8: 2M04 | C8: =_xlfn.XLOOKUP(D8,工作表1!C:C,工作表1!A:A) -> 1001021597 | D8: 機場捷運店 | E8: 2022-12-02 19:30:00 | F8: 2022-12-02 19:30:00 | G8: 0.55
A9: False | B9: 2MDC | D9: 林口ＤＣ | E9: 2022-12-02 19:50:00 | F9: 2022-12-02 19:50:00 | G9: 0
B10: 2N | D10: 林口ＤＣ | G10: 11.25 | H10: 0.78125
A11: False | B11: 2N01 | C11: =_xlfn.XLOOKUP(D11,工作表1!C:C,工作表1!A:A) -> 1001015407 | D11: 林口麗林店 | E11: 2022-12-03 06:00:00 | F11: 2022-12-03 06:00:00 | G11: 1.72
A12: False | B12: 2N02 | C12: =_xlfn.XLOOKUP(D12,工作表1!C:C,工作表1!A:A) -> 1001022531 | D12: 林口新都店 | E12: 2022-12-03 06:30:00 | F12: 2022-12-03 06:30:00 | G12: 0.66
A13: False | B13: 2N03 | C13: =_xlfn.XLOOKUP(D13,工作表1!C:C,工作表1!A:A) -> 1001022230 | D13: 林口影城店 | E13: 2022-12-03 06:45:00 | F13: 2022-12-03 06:45:00 | G13: 1.25
A14: False | B14: 2N04 | C14: =_xlfn.XLOOKUP(D14,工作表1!C:C,工作表1!A:A) -> 1001017041 | D14: 林口菁英店 | E14: 2022-12-03 07:00:00 | F14: 2022-12-03 07:00:00 | G14: 0.57
A15: False | B15: 2N05 | C15: =_xlfn.XLOOKUP(D15,工作表1!C:C,工作表1!A:A) -> 1001019267 | D15: 龜山大義店 | E15: 2022-12-03 07:15:00 | F15: 2022-12-03 07:15:00 | G15: 0.86
A16: False | B16: 2N06 | C16: =_xlfn.XLOOKUP(D16,工作表1!C:C,工作表1!A:A) -> 1001021576 | D16: 龜山甲子店 | E16: 2022-12-03 07:40:00 | F16: 2022-12-03 07:40:00 | G16: 1.45
A17: False | B17: 2N07 | C17: =_xlfn.XLOOKUP(D17,工作表1!C:C,工作表1!A:A) -> 1001021558 | D17: 龜山善捷店 | E17: 2022-12-03 07:50:00 | F17: 2022-12-03 07:50:00 | G17: 0.93
A18: False | B18: 2N08 | C18: =_xlfn.XLOOKUP(D18,工作表1!C:C,工作表1!A:A) -> 1001017360 | D18: 龜山新都店 | E18: 2022-12-03 08:20:00 | F18: 2022-12-03 08:20:00 | G18: 0.31
A19: False | B19: 2N09 | C19: =_xlfn.XLOOKUP(D19,工作表1!C:C,工作表1!A:A) -> 1001016068 | D19: 龜山新城店 | E19: 2022-12-03 08:35:00 | F19: 2022-12-03 08:35:00 | G19: 1.59
A20: False | B20: 2N10 | C20: =_xlfn.XLOOKUP(D20,工作表1!C:C,工作表1!A:A) -> 1001022088 | D20: 龜山庚勤店 | E20: 2022-12-03 08:55:00 | F20: 2022-12-03 08:55:00 | G20: 0.07
A21: False | B21: 2N11 | C21: =_xlfn.XLOOKUP(D21,工作表1!C:C,工作表1!A:A) -> 1001021758 | D21: 龜山長明店 | E21: 2022-12-03 09:15:00 | F21: 2022-12-03 09:15:00 | G21: 1.02
A22: False | B22: 2N12 | C22: =_xlfn.XLOOKUP(D22,工作表1!C:C,工作表1!A:A) -> 1001018725 | D22: 龜山庚德店 | E22: 2022-12-03 09:30:00 | F22: 2022-12-03 09:30:00 | G22: 0.12
A23: False | B23: 2N14 | C23: =_xlfn.XLOOKUP(D23,工作表1!C:C,工作表1!A:A) -> 1001016413 | D23: 龜山大湖店 | E23: 2022-12-03 10:20:00 | F23: 2022-12-03 10:20:00 | G23: 0.7
A24: False | B24: 2NDC | D24: 林口ＤＣ | E24: 2022-12-03 10:31:00 | F24: 2022-12-03 10:31:00 | G24: 0
B25: 2S | D25: 林口ＤＣ | G25: 11.28 | H25: 0.78333333
A26: False | B26: 2S01 | C26: =_xlfn.XLOOKUP(D26,工作表1!C:C,工作表1!A:A) -> 1001016401 | D26: 林口菁埔店 | E26: 2022-12-03 06:30:00 | F26: 2022-12-03 06:30:00 | G26: 0.72
A27: False | B27: 2S02 | C27: =_xlfn.XLOOKUP(D27,工作表1!C:C,工作表1!A:A) -> 1001015867 | D27: 林口南林店 | E27: 2022-12-03 06:50:00 | F27: 2022-12-03 06:50:00 | G27: 0.45
A28: False | B28: 2S03 | C28: =_xlfn.XLOOKUP(D28,工作表1!C:C,工作表1!A:A) -> 1001017243 | D28: 五股芳洲店 | E28: 2022-12-03 07:20:00 | F28: 2022-12-03 07:20:00 | G28: 1.15
A29: False | B29: 2S04 | C29: =_xlfn.XLOOKUP(D29,工作表1!C:C,工作表1!A:A) -> 1001016882 | D29: 五股洲子洋店 | E29: 2022-12-03 07:40:00 | F29: 2022-12-03 07:40:00 | G29: 1.16
A30: False | B30: 2S05 | C30: =_xlfn.XLOOKUP(D30,工作表1!C:C,工作表1!A:A) -> 1001017853 | D30: 五股新五店 | E30: 2022-12-03 08:00:00 | F30: 2022-12-03 08:00:00 | G30: 0.87
A31: False | B31: 2S06 | C31: =_xlfn.XLOOKUP(D31,工作表1!C:C,工作表1!A:A) -> 1001020723 | D31: 八里龍米店 | E31: 2022-12-03 08:30:00 | F31: 2022-12-03 08:30:00 | G31: 1.09
A32: False | B32: 2S07 | C32: =_xlfn.XLOOKUP(D32,工作表1!C:C,工作表1!A:A) -> 1001020456 | D32: 八里船頭店 | E32: 2022-12-03 08:50:00 | F32: 2022-12-03 08:50:00 | G32: 0.6
A33: False | B33: 2S08 | C33: =_xlfn.XLOOKUP(D33,工作表1!C:C,工作表1!A:A) -> 1001021847 | D33: 八里左岸店 | E33: 2022-12-03 09:10:00 | F33: 2022-12-03 09:10:00 | G33: 0.95
A34: False | B34: 2S09 | C34: =_xlfn.XLOOKUP(D34,工作表1!C:C,工作表1!A:A) -> 1001020726 | D34: 八里中廣店 | E34: 2022-12-03 09:30:00 | F34: 2022-12-03 09:30:00 | G34: 0.86
A35: False | B35: 2S10 | C35: =_xlfn.XLOOKUP(D35,工作表1!C:C,工作表1!A:A) -> 1001017885 | D35: 八里華城店 | E35: 2022-12-03 09:45:00 | F35: 2022-12-03 09:45:00 | G35: 0.73
A36: False | B36: 2S11 | C36: =_xlfn.XLOOKUP(D36,工作表1!C:C,工作表1!A:A) -> 1001016467 | D36: 八里中華店 | E36: 2022-12-03 10:00:00 | F36: 2022-12-03 10:00:00 | G36: 0.7
A37: False | B37: 2S12 | C37: =_xlfn.XLOOKUP(D37,工作表1!C:C,工作表1!A:A) -> 1001017641 | D37: 八里廖添丁店 | E37: 2022-12-03 10:15:00 | F37: 2022-12-03 10:15:00 | G37: 0.73
A38: False | B38: 2S13 | C38: =_xlfn.XLOOKUP(D38,工作表1!C:C,工作表1!A:A) -> 1001018483 | D38: 林口洪福店 | E38: 2022-12-03 10:40:00 | F38: 2022-12-03 10:40:00 | G38: 1.27
A39: False | B39: 2SDC | D39: 林口ＤＣ | E39: 2022-12-03 11:29:00 | F39: 2022-12-03 11:29:00 | G39: 0
B40: 2U | D40: 林口ＤＣ | G40: 12.38 | H40: 1.238
...

Sheet 工作表2
A1: 車次 | B1: ID
A2: 2M
A3: 2M02 | B3: 1001018520
A4: 2M03 | B4: 1001018687
A5: 2M04 | B5: 1001021597
A6: 2MDC
A7: 2N
A8: 2N01 | B8: 1001015407
A9: 2N02 | B9: 1001022531
A10: 2N03 | B10: 1001022230
A11: 2N04 | B11: 1001017041
A12: 2N05 | B12: 1001019267
A13: 2N06 | B13: 1001021576
A14: 2N07 | B14: 1001021558
A15: 2N08 | B15: 1001017360
A16: 2N09 | B16: 1001016068
A17: 2N10 | B17: 1001022088
A18: 2N11 | B18: 1001021758
A19: 2N12 | B19: 1001018725
A20: 2N14 | B20: 1001016413
A21: 2NDC
A22: 2S
A23: 2S01 | B23: 1001016401
A24: 2S02 | B24: 1001015867
A25: 2S03 | B25: 1001017243
A26: 2S04 | B26: 1001016882
A27: 2S05 | B27: 1001017853
A28: 2S06 | B28: 1001020723
A29: 2S07 | B29: 1001020456
A30: 2S08 | B30: 1001021847
A31: 2S09 | B31: 1001020726
A32: 2S10 | B32: 1001017885
A33: 2S11 | B33: 1001016467
A34: 2S12 | B34: 1001017641
A35: 2S13 | B35: 1001018483
A36: 2SDC
A37: 2U
A38: 2U01 | B38: 1001020993
A39: 2U02 | B39: 1001022307
A40: 2U03 | B40: 1001019377
...

Sheet 工作表1
A1: 店鋪編號 | B1: DC別 | C1: 店鋪名稱 | D1: 店鋪地址 | E1: 經度 | F1: 緯度 | G1: 營業狀態 | H1: 夜間熄火 | I1: 不可大車 | J1: 不可爆量 | K1: 不可進店時段1 | L1: 不可進店時段2 | M1: 不可進店時段3
A2: 1001022683 | B2: 林口DC | C2: 新衡山店 | D2: 台北市中山區通北街１１１號 | E2: 121.538003000002 | F2: 25.0843040004376 | G2: 啟用 | H2: 是 | I2: 否 | J2: 否
A3: 1001022678 | B3: 林口DC | C3: 新莊萬安店 | D3: 新北市新莊區萬安街８０號 | E3: 121.420756000001 | F3: 25.023062000444 | G3: 啟用 | H3: 否 | I3: 否 | J3: 否
A4: 1001022674 | B4: 林口DC | C4: 五股維興店 | D4: 新北市五股區四維路７８號．８０號１樓 | E4: 121.467470000002 | F4: 25.0729070004433 | G4: 啟用 | H4: 否 | I4: 否 | J4: 否
A5: 1001022673 | B5: 林口DC | C5: 永和新廷店 | D5: 新北市永和區福和路３２０號１樓 | E5: 121.515708000002 | F5: 25.0073500004378 | G5: 啟用 | H5: 否 | I5: 否 | J5: 否
A6: 1001022651 | B6: 林口DC | C6: 三重集勇店 | D6: 新北市三重區集勇街１９號 | E6: 121.485095000002 | F6: 25.0851930004425 | G6: 啟用 | H6: 否 | I6: 否 | J6: 否
A7: 1001022650 | B7: 林口DC | C7: 錦西店 | D7: 台北市中山區錦西街８號 | E7: 121.521700000002 | F7: 25.0601540004387 | G7: 啟用 | H7: 否 | I7: 否 | J7: 否
A8: 1001022642 | B8: 林口DC | C8: 酒泉店 | D8: 台北市大同區庫倫街４８之４號 | E8: 121.518318000002 | F8: 25.0717690004393 | G8: 啟用 | H8: 否 | I8: 否 | J8: 否
A9: 1001022640 | B9: 林口DC | C9: 新莊超級店 | D9: 新北市新莊區莊崑路２５號１樓 | E9: 121.431353000002 | F9: 24.9995860004429 | G9: 啟用 | H9: 否 | I9: 否 | J9: 否
A10: 1001022639 | B10: 林口DC | C10: 淡水紅林店 | D10: 新北市淡水區八勢里中正東路二段６９號１樓 | E10: 121.459589000002 | F10: 25.1546070004461 | G10: 啟用 | H10: 否 | I10: 否 | J10: 否
A11: 1001022622 | B11: 林口DC | C11: 龍廣店 | D11: 台北市萬華區廣州街２０３號１．２樓 | E11: 121.500359000002 | F11: 25.0367310004399 | G11: 啟用 | H11: 否 | I11: 否 | J11: 否
A12: 1001022621 | B12: 林口DC | C12: 新廣州店 | D12: 台北市萬華區廣州街２３５－１號、２３５－２號 | E12: 121.498613000002 | F12: 25.0368370004401 | G12: 啟用 | H12: 否 | I12: 否 | J12: 否
A13: 1001022620 | B13: 林口DC | C13: 新格致店 | D13: 台北市士林區格致路５３號１樓 | E13: 121.546425000002 | F13: 25.137725000438 | G13: 啟用 | H13: 否 | I13: 否 | J13: 否
... A726: 1001005989 | B726: 林口DC | C726: 中賓店 | D726: 台北市中山區中山里中山北路二段５９之３號１樓 | E726: 121.523163437784 | F726: 25.0561398734651 | G726: 啟用 | H726: 否 | I726: 否 | J726: 否
